Workbook

Sheet HEWSs
B1: This table summarizes information about Heat Early Warning Systems (HEWS) in Europe and associated countries of PROCLIAS. Currently, it is based on Casanueva et al. (2019) (their Table 1, 2 and 4)
B2: Please fill in missing information and update it if possible
B4: INFORMATION ON CURRENT HEWS | L4: FIRST HEWS | M4: MAJOR UPDATES | O4: GENERAL COMMENTS
A5: COUNTRY/CITY | B5: PROVIDER / INSTITUTION | C5: IMPLEMENTATION YEAR OF CURRENT WARNING SYSTEM | D5: MODEL SYSTEM | E5: LEAD TIME | F5: SPATIAL RESOLUTION | G5: HEAT INDEX | H5: WARNING THRESHOLDS/ALERT LEVELS | I5: NATURE OF THE WARNING THRESHOLDS | J5: TARGET GROUPS | K5: COMMUNICATION TOOLS | L5: IMPLEMENTATION YEAR OF FIRST WARNING SYSTEM | M5: YEARS OF UPDATES | N5: SHORT DESCRIPTION OF UPDATES | P5: last year of update/implementation
A6: ALBANIA
A7: AUSTRIA | B7: Zentralanstalt für Meteorologie und Geodynamik (ZAMG) | D7: INCA (1 km), ALARO (5 km), ECMWF ENS (15 km) | E7: 6 h (INCA), 72 h (ALARO) | F7: Regional | G7: Perceived Temperature (PT) and Tmin | H7: PT > 35 for at least 3 days without night cooling below 20 Thresholds are subject to modifications depending on weather in preceding days. | I7: Threshold from epidemiological studies (based on thermophysiological strain) in Germany by DWD adapted to Austria. | J7: Nursing facilities, hospitals and health resorts, childcare facilities (kindergartens, schools, etc.), mobile nursing services, medical chambers and emergency organizations | K7: Website
A8: BELGIUM | B8: Royal Meteorological Institute of Belgium (RMI) | C8: 2005 | D8: ALADIN (deterministic) + RMI EPS (probabilistic, based on AROME and ALARO, 2.5 km) | E8: 12–48 h, depending on the warning level | F8: Provinces | G8: Tmax, Tmin, Tcumul | H8: Green: No warning, all indices below thresholds. Yellow: Tcumul ≥ 17 ◦ C Orange: 2 day mean with Tmax ≥ 32 ◦ C and Tmin ≥ 20 ◦ C or 3 day mean Tmax ≥ 30 ◦ C and Tmin ≥ 18 ◦ C Red: 3 day mean Tmax ≥ 32 ◦ C and Tmin ≥ 20 ◦ C | J8: Belgium Interregional Environment Agency (IR-CEL), authorities | K8: Bulletin journalier, dépliants, mails, site Internet. | O8: color codes also linked to warnings for extreme precipitation, storm and other meteorological extremes
A9: CROATIA | B9: hrvatski zavod za javno zdravstvo | C9: 2012 | D9: ALADIN, ECMWF, DWD | F9: 8 regions | G9: Tmax, Tmin (PET) | H9: 3 levels, T > 96.5 percentile, T > 98.5 percentile, T > 99.5 percentile (13<PET<18 : slight cold stress 18<PET<23 : no thermal stress 23<PET<29 : slight thermal stress ; 29<PET<35 : moderate heat stress ; PET>35 : strong heat sress) | I9: Based on epidemiological data…Zaninovic and Matzarakis 2011 and 2014 | J9: County PHIs Hospitals Croatian Institute of Emergency Medicine - NN071 / 2012 Reference center of the Ministry of Health for the protection of the health of the elderly Ministry of Demography, Family, Youth and Social Policy Croatian Institute for Occupational Health and Safety Croatian Institute for Health Insurance Ministry of Science and Education Croatian Red Cross DUZS - State Administration for Protection and Rescue Tourist board HINA | K9: emails, website, TV
A10: CZECH REPUBLIC | B10: Czech Hydrometeorological Institute | C10: 2019 | D10: ALADIN (2.3 km) based on the global model ARPAGE, cross validated with ICON, GFS, ECMWF, GEM | E10: warnings for 48h; 3-5 days for preliminary warnings | F10: 152 major municipalities | G10: Tmax | H10: three alert levels (yellow, orange, red) based on the intensity and probability of the event: Tmax > 31, 34, 37 °C; | I10: climatology based thresholds | J10: the national fire department, regional and local authorities, general public | K10: public media, social media, website, phone application | L10: 2000 | M10: 2006; 2012; 2019; | N10: 2000 (two levels: Tmax > 32 °C and 37 °C); 2006 (three level system:Tmax > 30 °C, 34 °C, 37 °C in at least 30% of the region area; warnings for districts (76)); 2012 (three level system: Tmax > 31 °C, 34 °C, 37 °C in at least 50% of the region area); 2019 (three level system: Tmax > 31 °C, 34 °C, 37 °C, warnings for major municipalities (152) instead of districts (76)); | O10: similar three level system for other severe weather events | P10: 2019
A11: DENMARK | B11: Beredskabsstyrelsen (Emergency Agency) www.brs.dk ,on the basis of weather data from Danish Meteorological Institute | D11: DMI weather models(many), including for Greenland and Færø Islands and Bornholm | E11: 12-72 h | F11: Kommunalt beredskab (district level); special services for shipping and sea transports (ice situations) | G11: Tmax, Tmin | H11: Tmax > 30-C ; Tmin < (-10 -C) | J11: Two groups: general population, and selected organizations (dependent on their activities) | K11: Institutional command lines from Beredskabsstyrelsen to local districts , civil defense and hospitals; media reports for general public | L11: For cold situations and Greenland, early 1950's; for heat situations from 2003 ; labour law aspects implemented in law and policy since 09/6/2016 political agreement | O11: On the issue of labour regulations under temperature stess conditions affecting health of workers , the union 3F (www.3f.dk) is very active, and the Court for Labour conditions has a guidebook https://www.basse.dk/erhvervsmiljøretten.html
A12: ESTONIA | B12: Estonian Weather Service http://www.ilmateenistus.ee/ilm/prognoosid/hoiatused/?lang=en | C12: 2021 | D12: ECMWF, MetCOOP, Hirlam | E12: 1-2 days | F12: county level | G12: Tmax, Tmin, Tavg | H12: 1. Yellow - Tmax ≥ 27-C more than 3 days ; Tmin < (-26 -C) more than 3 days; daily average ≥ 20-C more than 3 days 2. Orange - - Tmax ≥ 30-C more than 3 days ; Tmin < (-30 -C) more than 3 days; daily average ≥ 25-C more than 3 days | I12: warning thresholds are based on the human limits of suffering | J12: Warnings are issued as public warnings, but are target especialy for vulnerable risk groups | K12: Website, app, facebook, instagram, e-mails to the interest groups, internetportals, in the radio and TV news, newsapers | L12: 1991 | M12: 2001; 2011, 2017 | N12: change of input and delivery systems | P12: 2021
A13: FINLAND | B13: Finnish Meteorological Institute (FMI) | C13: 2011 | D13: AROME, ECMWF, final decision about issuing the warnings by the forecaster in duty | E13: 5 days | F13: county level (Regional Councils in Finland) or larger area | G13: Combinations of daily Tmax and Tmean | H13: 1. (yellow): hot - Tmax>27 and Tmean>20; 2. (orange) - very hot - Tmax>30 and Tmean>24; 3. (red) - extremly hot - Tmax>35 and Tmean>28 degrees C ( https://en.ilmatieteenlaitos.fi/warnings-on-hot-and-cold-weather) | I13: epidemiological research, climatic conditions, acceptability of the warnings, operational service process | J13: Warnings are issued as public warnings, but are target especialy for vulnerable risk groups | K13: FMI website. YLE, National Broadcating Company. FMI weather warnings are freely available for all interested users - available also in FMI open data | L13: 2011 | M13: 2017 | N13: 3 day warning criteria was removed, Tmin was replaced by Tmean in warning criteria | O13: The HEWS is part of FMI operational 3-level weather warning system https://en.ilmatieteenlaitos.fi/information-on-warnings | P13: 2017
A14: FRANCE | B14: MeteoFrance and Santé Publique France | C14: 2004 | D14: AROME (1.3 km) + ARPEGE (16 km), deterministic | E14: 36 h (AROME), 4 days (ARPEGE) | F14: Departmental | G14: Combination of Tmin and Tmax averaged over three days (BMI) | H14: 3 days mean of Tmax > regionally dependent thresholds and 3 days mean of Tmin > regionally dependent thresholds three colours level, not strict the warning is set depending on the probability of exceeding the thresholds | I14: epidemiological research Biometeorological | J14: local authorities and the general population | K14: Communicated to the media and the general population by MétéoFrance through a vigilance map | M14: the main update was in 2019 the changes of criteria for the red level | P14: 2019
A15: GERMANY | B15: German Weather Service (DWD) | C15: 2005 | D15: MOSMIX (optimizes and interprets the forecasts of ICON-DWD and IFS-ECMWF) | E15: 2 days (8 days for pre-information) | F15: County level | G15: PT and Tmin | H15: Thresholds are region-specific and consider acclimatization (previous 30 days). Benchmark: Level 1: 20 ◦ C < PT < 26 ◦ C Level 2: 26 ◦ C < PT < 32 ◦ C Level 3—Strong heat stress: 32 ◦ C < PT < 38 ◦ C & Tmin ≥ 17 ◦ C Level 4—Extreme heat stress: PT ≥ 38 ◦ C & Tmin ≥ 17 ◦ C Only Levels 3 and 4 are relevant for heat warnings. | I15: Epidemiological research, based on thermophysiological strain | J15: General public, health system, elderly, people living socially isolated, people needing care, obese persons, chronically ill, working people outdoors, homeless, babies and infants. | K15: Email-Newsletter, website, Apps, radio, internet, newspaper, television | P15: 2005 ?
A16: GREECE | B16: Hellenic National Meteorological Service (HNMS) | D16: ECMWF deterministic and ENS model | E16: 3 days | F16: Regional (16 regions) | G16: Tmax and heat index | H16: a. For Tmax over the northern Greek regions: 35 ◦ C ≤ Tmax < 39 ◦ C (yellow), 39 ◦ C ≤ Tmax < 42 ◦ C (amber), Tmax ≥ 42 ◦ C (red) b. For Tmax over the Central and Southern parts of Greece: 37 ◦ C ≤ Tmax < 41 ◦ C (yellow), 41 ◦ C ≤ Tmax < 44 ◦ C (amber), Tmax ≥ 44 ◦ C (red) c. For Tmax over the islands: 33 ◦ C ≤ Tmax < 37 ◦ C (yellow), 37 ◦ C ≤ Tmax ≤ 40 ◦ C (amber), Tmax ≥ 40 ◦ C (red) Heat index used as a supplementary tool in order to enhance the conclusions from the consideration of each synoptic situation. No thresholds related. | I16: Climatological percentiles and the respective literature | J16: General Public. Other target groups are managed by the Ministry of Health | K16: Website, twitter
A17: HUNGARY | B17: Hungarian Meteorological Service (HMS) and National Public Health and Medical Officer Service (ANTSZ) | D17: ECMWF and GFS, both with deterministic and probabilistic versions | E17: 4 days to the public, 8 days to the authorities | F17: Minimum unit is county level | G17: Tmean | H17: Yellow : 25 ◦ C > Tmean > 27 ◦ C Orange: 27 ◦ C > Tmean > 29 ◦ C Red: Tmean ≥ 29 ◦ C | I17: Epidemiological, link to mortality | J17: National Public Health and Medical Officer Service | K17: Website, mobile app (Meteora)
A18: IRELAND | B18: MET éireann : https://www.met.ie/met-eireann-warning-system-explained | G18: Tmax and Tmin | H18: Level green : Tmax < 27°C. Level yellow : Tmax >27°C Level orange : Tmax >30°C and Tmin >20°C (24h period) Level red : Tmax >30°C and Tmin >20°C for 2 nights or more | I18: Meteorological | J18: People at risk because of their location or activity
A19: ISRAEL
A20: ITALY | B20: , Lazio Health Authority and Department of Epidemiology, national centre for heat and health prevention CIVIL PROTECTION | C20: 2004 | D20: COSMO deterministic (5 and 2.2 km,depending on the domain) + COSMO-EPS(probabilistic, 7 and 2.2 km) | E20: 72 h | F20: Regional capitals and cities with more than 250,000 inhabitants (27 cities) | G20: Tappmax and “air mass-based approach” in larger cities | H20: City-specific and month specific | I20: Epidemiological, related to excess mortality | J20: Ministry of Health, regional Health services, local health authorities, local civil protection, Municipalities and social services, (hospitals, retirement homes etc.) GPs, media, NGOs and associations and care givers who assist the elderly and vulnerable subgroups. Citizen science associations. | K20: City-specific warning bulletins avaiable on line on MOH website and local webistes. Bulletins are distributed through the information network both national, regional and local level via email to each designanted focal point which is then in charge of local dissemination. Diffusion of warnings via the media, Ministry of Health/Civil Protection websites. Caldo e salute APP and directly within active surveillance APPS and web portals. New version will be lauched in 2022. | L20: 2003 | M20: 2006,2010,2015 | N20: extended to all 27 cities in 2006, revised airmasses and thresholds in more recent years to account for changes in heat response and climatic conditions (adaptation) and to account for ageing of the population. HEWs should be dynamic as the local vulnerbale population | P20: 2015
A21: NETHERLANDS | B21: National Institute for Public Health and the Environment (RIVM) and Royal Netherlands Meteorological Institute (KNMI) | C21: 2007 | D21: HIRLAM + HARMONIE (2.5 km) + ECMWF ENS (9 km) | E21: 6 days | F21: Regional | G21: Tmax | H21: more than 10% probability of 4 or more days with Tmax > 27 ◦ C | I21: Epidemiological, related to excess of mortality | J21: Elderly, people in care institutions, and chronically ill and overweight people. Public health services, trade associations and the Dutch Red Cross | K21: Letters, media (press release), emails etc. | O21: https://bmchealthservres.biomedcentral.com/track/pdf/10.1186/1472-6963-13-135.pdf | P21: 2007 ?
A22: NORTH MACEDONIA | B22: Macedonian Meteorology | E22: 2 days | F22: National and regional | G22: Tmax | H22: Monthly thresholds for each of the 4 phases for 13 cities in 6 regions from May to September | I22: Practical: not too many warnings in a year | J22: Retirement homes, GPs, workers. | K22: Communication with the public, the health, educational and social sectors, recommendations for health workers, the population and risk groups before and during the heat wave.
A23: NORWAY | B23: MET Norway | C23: Do not issue weather warning, only monitoring from 2022 | D23: Harmonie Arome | E23: 0 - 5 | F23: Regional and specific (station based) | G23: TMAX and TMIN | H23: "norwegian heatwave" definition: Mean TMAX>=28 deg over 5 days AND Mean TMIN>=16 deg over 5 days | I23: Every second year in southern part of Norway where many people lives in cities | J23: Vulnear people (elderly and sick, babies) | K23: Twitter, radio, phone-calls from media/newspapers | L23: No warning, only monitoring from 2022 | O23: Collaboration with Health authorities has started to find impacts and how to go further | P23: 2022
A24: POLAND | B24: Institute of Meteorology and Water Management–State Research Institute | D24: ALARO | E24: 72h | F24: 4km | G24: Tmin, Tmax | H24: three alert levels 1)Yellow if the following conditions apply simultaneously: - Tmax ≥ 30° C, - Tmin < 18°C, - Duration ≥ 2 days. 2)Orange if the following conditions apply simultaneously: 30° C ≤ Tmax ≤ 34° C, - Tmin ≥ 18° C, - Duration ≥ 2 days. 3)Red Yellow if the following conditions apply simultaneously: -Tmax > 35° C, - Tmin ≥ 18° C, - Duration ≥ 2 days. | I24: Climatology-based values | J24: Public (general population) State administration at various levels, Local authorities | K24: Institute of Meteorology and Water Management app and website. SMS alerts via mobile operators based on approximate users location. Press, Radio, Televisions
A25: PORTUGAL | B25: Portuguese Meteorological Institute, Portuguese National Institute of Health, Portuguese General Health Directorate and Portuguese Civil Protection Service | C25: 1999 | D25: ALADIN (12 km) | E25: 3 days | F25: Regional and specific for Lisbon | G25: For heat wave definition: TemperatureFor alert levels: ÍCARO index | H25: Heat wave: Temperature > 32 ◦ C for at least 2 days Level 1 & 2: ÍCARO index < 0.31 Level 3: ÍCARO index 0.31–0.93 Level 4 (Heat-wave alert): ÍCARO index > 0.93 | I25: Epidemiological | J25: Portuguese National Institute of Health, the Portuguese Meteorological Institute, Portuguese General Health Directorate and the Portuguese Civil Protection Service | K25: Institute of Meteorology and Water Management app and website. SMS alerts via mobile operators based on approximate users location. Press, Radio, Televisions | P25: 2019
A26: ROMANIA | B26: Health Ministry and National Meteorological Administration | C26: 2006 | D26: ECMWF(10 days, deterministic and ensemble) ALADIN/ALARO (6.5 km resolution, up to 78 h) COSMO (7 km resolution, up to 78 h) COSMO (2.8 km resolution, up to 30 h) ICON (2.8 km resolution, up to 78 h) | E26: 1-4 days | F26: National and regional | G26: Tmax / Tmin Temperature / Humidity Index | H26: Yellow code: Tmax 37 - 39°C for SV and S Romania; Tmax 35-37°C for other regions; Or/and Temperature/Humidity Index over 80 units. Orange code: Tmax 39-42°C for SV and S Romania; Tmax 37-39°C for other regions. Red code: Tmax over 42°C for SV and S Romania; Tmax 39-40°C for other regions. | I26: Climatological | J26: Local and national authorities, civil protection, ministries, red cross, mass media, general public | K26: Website, mailing lists, mass media, social media | L26: 2006 | M26: 2014 | N26: updated thresholds | P26: 2014
A27: SERBIA | B27: Republic Hydrometeorological Service of Serbia | C27: 2013, 2016 | D27: ECMWF HRES (8 km), NMM (4 km) | E27: 10 days, 3 days | F27: Districts and cities, National Spatial Distribution | G27: Tmax, THI Temperature Humidity Index | H27: Tmax tresholds city/region based for 3 categories: potentially dangerous, dangerous and extremely dangerous. Heat wave with at least 3 consecutive days in dangerous or extremely dangerous category, for THI = 26-32 C - caution; 33-41 C - increased attention; 42-54 C - danger; >54 C extreme danger | I27: Climatology based percentiles, Infuence on human health | J27: General population, Institute of Public Health of Serbia | K27: Website (maps, Bulletins), Public media, emails | L27: 2007 | M27: 2012, 2016 | N27: New criteria for HW, THI introduced | O27: For more info please contact Dragan Mihic from national meteorological service dragan.mihic@hidmet.gov.rs | P27: 2016
A28: SLOVAKIA | B28: Slovak Hydrometeorological Institute https://www.shmu.sk/sk/?page=1 | C28: 2012 | D28: ECMWF, ALADIN | E28: 3 days | F28: available for 79 districts in Slovakia, according the division since 1996 | G28: Tmax | H28: 3 warnings thresholds 1. yelllow: Tmax> 33 ◦ C, 2. orange: Tmax> 35 ◦ C nad 3. red: Tmax> 38 ◦ C | I28: Climatology-based values | J28: Public (general population), civil defense, mayors of the cities or red warning | K28: Website, mailing lists, media, social media. https://www.shmu.sk/sk/?page=987 | L28: 2012, implematation within the frame of Meteoalarm EU | M28: 2017 | P28: 2017
A29: SLOVENIA | B29: Slovenian Environment Agency (ARSO) | C29: 2011 | D29: ECMWF and Aladin | E29: 5 days | F29: 5 regions—approximately 4000 km^2 each | G29: Tmean and Tmax | H29: Yellow: Tmax > 31 ◦ C Orange: Tmax > 34 ◦ C and/or Tmean > 26 ◦ C Red: Tmax > 37 ◦ C and/or Tmean > 28 ◦ C Tresholds are regionally-based | I29: Climatology-based percentiles | J29: Public (general population), civil defense in case of orange or red warning | K29: public media
A30: SPAIN | B30: National Plan joining several institutions (e.g., National Meteorological Agency AEMET, Health Ministry) | C30: 2006 (METEOALERT) | D30: HARMONIE-AROME (deterministic) + IFS-ECMWF (probabilistic, longer lead times) | E30: 3 days (HARMONY-AROME), 5 days (IFS-ECMWF) | F30: Regions and provinces | G30: Heat wave: Tmax HHAP: Tmax and Tmin | H30: Heat wave: At least 3 days with at least 10% of stations in the region with Tmax > 95th percentile. Warnings for single-day events (yellow | orange | red corresponding to different Tmax for each region: North 34 | 37 | 40; Center and Med. 36 | 39 | 42; South 38 | 40 | 44). HHAP: Level 1: 1–2 days Tmax and Tmin above threshold simultaneously Level 2: 3–4 days above threshold Level 3: 5 days above threshold | I30: Heat wave: Climatological percentiles for each region. HHAP: temperature triggering mortality. | J30: General population, Civil Protection, Maritime Rescue Centers, Department of Traffic, Military Unit for Emergencies, Red Cross, other Met Services, government and ministries, media. | K30: Website (maps, bulletins and CAP), social media (especially Twitter), Open Data server for further analyses. | P30: 2006
A31: SPAIN >> CATALONIA | B31: Regional plan joining several institutions, e.g. Meteorological Service of Catalonia, Public Health Agency of Catalonia, Catalan Health Service. | C31: 2004, "Action Plan to Prevent the Effects of Heat Waves on Human Health" (POCS). | D31: WRF-ARW (using ECMWF IFS as ic/bc). | E31: 3 days at 27 km (Europe), 9 km (Iberian Peninsula) and 3 km (Eastern Spain). 2 days at 1.5 km (Catalonia). | F31: Information available for the 42 counties of Catalonia. For info: Catalonia has 4 NUTS3 regions, so these counties are very small. Their population vary from 2.2M (Barcelona county) to 4k (in the Pyrenees). More info: https://en.wikipedia.org/wiki/Comarques_of_Catalonia | G31: Maximum temperature. | H31: Level 1: <30% of extreme temperature. Level 2: 30-70% of extreme temperature. Level 3: >70% of extreme temperature. Level 4: <30% of heat wave. Level 5: 30-70% of heat wave. Level 6: >70% of heat wave. | I31: Extreme temperature: T > P98. Heat wave: 3 consecutive days of extreme temperature. | J31: Epidemiological Surveillance Network, the National Health Service, the Ministries of the Interior, Labour and Social Affairs, the Emergency Medical System, the Catalan Health Institute, the Federation of Cities, the Federation of Pharmacies, the Legal and Forensic Medical Institute, the Union of Hospitals, the Social Network Consortium and the Red Cross, among many others. | K31: Website, mailing lists, media, social media. | L31: 2000. | M31: 2009, 2012 | N31: 2009: new definition criterion. 2012: new application and database that reduced the time of decision making. | P31: 2012
A32: SPAIN >> MADRID | B32: Dirección General de Salud Pública CONSEJERÍA DE SANIDAD. COMUNIDAD DE MADRID | C32: 2004 | F32: Region | G32: Tmax | H32: Level 0 : 5 days with Tmax<36,5°C. Level 1 : 3 days with Tmax <38,5°C. Level 2 : Tmax > 38,5°C or 4 days with Tmax>36,5°C | I32: Los criterios están basados en el análisis de series temporales de temperatura y mortalidad | L32: 2004
A33: SPAIN >> MURCIA | B33: Regional plan joining several institutions: -Regional Public Health Agency -National Meteorological Agency -Medical Emergencies Service -Environmental Health -Healthcare Service -Epidemiological Service -Health Promotion -Social Protection Institute -Civil Protection Service -Federation of Municipalities | C33: 2004 | D33: Provided by AEMET (Spanish Meteorological Agency) HARMONIE-AROME (deterministic) + IFS-ECMWF (probabilistic, longer lead times) | E33: 3 days (HARMONY-AROME), 5 days (IFS-ECMWF) | F33: Sub-regional: 5 isoclimate areas | G33: IDET Index (Extreme Temperatures Daily Index) | H33: Level 0 (Green): 0 days with Tmax and Tmin simultaneously above threshold Level 1 (Yellow): 1-2 days with Tmax and Tmin simultaneously above threshold Level 2 (Orange): 3-4 days with Tmax and Tmin simultaneously above threshold Level 3 (Red): 5 days with Tmax and Tmin simultaneously above threshold | I33: Tmin>23C Tmax>34C | J33: IDET Index disseminated daily to >80 target groups, including Health-care Centres, Hospitals, City Councils, Red Cross, Civil Protection, Media, among othes | K33: Website, mailing lists, media, social media. | L33: 2004 | M33: 2014, 2015 | N33: 2014: Only heat-related mortality is monitored. Previously, also morbiditiy cases were reported. 2015: Temperature thresholds modified. | P33: 2015
A34: SPAIN >> ANDALUSIA | B34: Plan Andaluz Temperaturas Excesivas | C34: 2004 | F34: Region | G34: Tmin Tmax | I34: basada en variables climatológicas y sanitarias obtenidas del análisis de las series históricas y de los estudios realizados | M34: 2015
A35: SWEDEN | B35: Swedish Meteorological and Hydrological Institute (SMHI) | C35: Action Plan to Prevent the Effects of Heat Waves on Human Health (POCS) - 2013 | D35: HARMONIE-AROME (0–48h, deterministic + probabilistic with 9 members) + ECMWF (longer lead times, deterministic and ENS) | E35: 3–5 days ahead depending on the warning criterion | F35: 40 warning districts of variable size. The warning is limited, if necessary, to a smaller part of the district | G35: Tmax | H35: Heat warning class 1: Tmax ≥ 30 ◦ C for 3 or 4 days Heat warning class 2: Tmax ≥ 30 ◦ C for at least 5 days or Tmax > 33 ◦ C for at least 3 days. Notification: Tmax ≥ 26 ◦ C for at least 3 days. Risk: same thresholds as for the class 2 warning, but the risk concept is used when the forecast is more uncertain. “notification” and “risk” are not considered warnings | I35: Epidemiological, based on the relation between temperature and rate of mortality. | J35: General public and health providers as hospitals, elderly care etc. | K35: Authorities and institutions in the health sector and in the elderly care can register to receive emails when heat warnings are issued | O35: https://www.ncbi.nlm.nih.gov/pmc/articles/PMC6713612/pdf/nihms-1047094.pdf | P35: 2013
A36: SWITZERLAND | B36: Federal Office of Meteorology and Climatology (MeteoSwiss) | C36: 2005, it was revised/updated in 2021 https://salutpublica.gencat.cat/ca/ambits/vigilancia_salut_publica/pocs | D36: COSMO CLM deterministic + MOSMIX + ENS ECMWF (longer lead times) | E36: COSMO 3 days, ENS ECMWF 5 days | F36: Regional | G36: Heat index | H36: Level 3 (orange): at least 3 days with HI > 90 Level 4 (red): at least 5 days with HI > 93 | J36: Construction industry, the trade unions (e.g., UNIA), local and cantonal authorities (including public health), general population | K36: MeteoSwiss app and website.Postal code subscription via app for receiving region-specific warnings. | L36: 2005 | M36: 2021 | N36: MeteoSwiss changed the warning thresolds and added a third alert level in 2021. The warnings are now based on Tmean. Level 2 (yellow): short, intense periods with Tmean ≥ 25 °C for one to two days. Level 3 (orange): Tmean ≥ 25 °C for at least three days. Level 4 (red): Tmean ≥ 27 °C on at least three days. Nature of warning thresholds: Epidemiological, based on the relation between temperature and rate of mortality. | P36: 2021
A48: TURKEY
A49: UK | B49: Met Office and Public Health England (PHE) | C49: Rochelle: Heat Health Watch Service (HHWS) operates in England since 2004 only during summetime [from 1 June to 15 September], except Level 0 which operates during all year. page13 - https://assets.publishing.service.gov.uk/government/uploads/system/uploads/attachment_data/file/888668/Heatwave_plan_for_England_2020.pdf | D49: Deterministic UK (UKV, 1.5 km) + Ensemble UK (MOGREPS-UK, 2.2 km) | E49: 120 h (UKV) to 5 days (MOGREPS-UK) | F49: Regional and local | G49: Tmax and Tmin Rochelle: Threshold Tmax day and Tmax night page 38 - https://assets.publishing.service.gov.uk/government/uploads/system/uploads/attachment_data/file/888668/Heatwave_plan_for_England_2020.pdf | H49: Region-specific (for Tmax and Tmin). Average thresholds: 30 ◦ C for Tmax and 15 ◦ C for Tmin for at least two consecutive days. Five alert levels (Levels 0–4). Rochelle: Level 0, active all year, is long-term planning to reduce the heat-related health risk. Level 1 starts at the beginning of summer and remains activated until 15 September, unless a temperature threshold is triggered. Levels 2 and 3 are activated if any Region-specific Met Office NSWWS threshold temperature is forecasted (Level 2) or reached (Level 3). Level 4 becomes a matter of national emergency because the hot weather is considered so severe and/or prolonged that it will surpass the health and social care impact boundaries. Pages 20-26 [actions on each level explained in details] Page 38 [threshold maximum day and night temperatures defined by the Met Office National Severe Weather Warning Service (NSWWS) region] https://assets.publishing.service.gov.uk/government/uploads/system/uploads/attachment_data/file/888668/Heatwave_plan_for_England_2020.pdf | I49: Epidemiological (15–20% increased risk of mortality) Rochelle: "Although excess seasonal deaths start to occur at approximately 25°C, for practical reasons the health heatwave alert system is based upon temperature thresholds where the odds ratio is above 1.15 to 1.2 (a 15 to 20% increased risk)." page 40 - https://assets.publishing.service.gov.uk/government/uploads/system/uploads/attachment_data/file/888668/Heatwave_plan_for_England_2020.pdf | J49: National Health Service, local authorities, social care, other public agencies, professionals working with people at risk, individuals, local communities, voluntary groups. | K49: Media, website, emails, social media, leaflet (via pharmacies, GPs, national health system, advice centres, hospitals, care homes) | L49: Rochelle: England since 2004 only during summetime | O49: Rochelle: Heatwave Plan for England: https://www.gov.uk/government/publications/heatwave-plan-for-england | P49: 2012

Sheet HHAP
B1: This table summarizes information about Heat Health Action Plans (HHAP) in Europe and associated countries of PROCLIAS. Part of the information is taken from Casanueva et al. (2019) (Table 3 and 4)
B2: Please fill in missing information and update it if possible
B4: BASIC INFORMATION ON HHAP | K4: DETAILS OF ACTIONS TAKEN | O4: GENERAL COMMENTS
A5: COUNTRY/CITY | B5: NAME OF PLAN AND IF AVAILABLE URL | C5: LEAD BODY | D5: IMPLEMENTATION YEAR OF CURRENT PLAN | E5: ACTIVE PERIOD DURING YEAR | F5: SPATIAL RESOLUTION | G5: LONG-TERM (URBAN) PLANNING [Yes/No] | H5: REAL-TIME SURVEILLANCE/ MORTALITY MONITORING [Yes/No] | I5: FREQUENCY OF REVISION AND EVALUATION | J5: ACTION PHASES | K5: TARGETED COMMUNICATION STRATEGY (DIRECTED AT GENERAL PUBLIC, HEALTH SECTOR, ADMINISTRATION, ETC.) [Yes/No] | L5: MEASURES TO REDUCE HEAT EXPOSURE (INDOOR AND OUTDOOR) [Yes/No] | M5: SPECIAL ATTENTION TO VULNERABLE PEOPLE [Yes/No] | N5: MEASURES DIRECTED AT HEALTH CARE SYSTEMS (HOSPITALS, NURSING HOMES ETC.) [Yes/No] | P5: last year of update / implementation
A6: ALBANIA
A7: Tirana
A8: AUSTRIA | D8: 2017 | J8: Level 0—Long-term development and planning for the summer: Elaboration and updating of information material and ensure information flow with stakeholders and other administrations. Level 1—protection during summer, between heat waves: preparation of information (general public and specific target groups), check and update emergency phone list. Level 2—during heat wave: - Transmission of heat warnings to umbrella organizations and sponsors of care facilities for the elderly andparticularly heat-sensitive population groups. - Management of hospitals, residential and care facilities and mobile services: - Increased attention to signs of heat-related illnesses. - Recording and documenting room-related heat stress (room temperature, solar radiation) and taking acute adaptation measures (ventilation behaviour, sun protection, changing the occupied zone) - Ensure sufficient availability and use of suitable beverages, monitor liquid balance of endangered persons. - Support cooling of the body (e.g., showers, hand and foot baths) and appropriate clothing, bed linen. - Ensure appropriate nutrition and food safety. - Avoidance of outdoor activities at peak times. - Family and neighborly contacts consciously activate - Phone line available for the population. | K8: yes | L8: Yes | M8: Yes | N8: Yes | O8: Preventive and direct actions
A9: Vienna
A10: BELGIUM | C10: Santé publiquen sécurité de la chaine alimentaire et environnement | E10: 15 May - 30 September | J10: Green : sensibilisation du public aux risques, encouragements à la solidarité envers les personnes vulnérables. Informations à tous les professionnels de santé, organisations sociales. Yellow : communiqués d'avertissement. Orange : campagne pour les soignant.es des personnes à risques, activation du centre d'appel. Red : phase d'urgence | L10: yes
A11: Brussels
A12: CROATIA | B12: Sustav upozorenja na toplinske valove ili klimatske promjene i zdravlje | C12: hrvatski zavod za javno zdravstvo | E12: 01/05 - 30/09 | J12: Level 0 : green, awareness ; Level 1 : yellow, warning/preparerness ; Level 2 : orange, heat wave ; Level 3 : red, emergency | K12: /
A13: CZECH REPUBLIC | B13: No HHAP up to date
A14: DENMARK | D14: 2003
A15: ESTONIA | B15: No HHAP up to date
A16: Kohtla-Järve linn
A17: Narva linn | D17: 1 DURING ALERT PHASE(S)
A18: Pärnu linn
A19: Tallinn
A20: Tartu linn
A21: FINLAND | B21: No HHAP up to date
A22: Helsinki
A23: FRANCE | B23: Plan National Canicule (till 2021) ORSEC guide | D23: PNC(2004) ORSEC Guide (2021) | E23: From 1st June till 15th September | J23: Upscale hotline staff. Track and support homeless (t-shirt, water, sun-cap, map of drinking fountains, emergency shelter venues). Voluntary registry of vulnerable people and monitoring (NGO, including Red Cross). Installation and maintenance of air-conditioned in residential care. Installation of public water provision or open up public swimming pools. | L23: yes | M23: yes
A24: GERMANY | B24: H a n d l u n g s e m p f e h l u n g e n für die Erstellung von Hitzeaktionsplänen zum Schutz der menschlichen Gesundheit | C24: Umweltbundesamt (leardship) | J24: Overall phone hotline and information campaign. | K24: No | L24: No | M24: No | N24: No | O24: Totally delegated to federal states. The National Plan does not contain cocrete meassures but only recommendations
A25: GREECE | D25: 2016 | O25: https://www.c40.org/case-studies/cities100-athens-heatwave-action-plan-protects-vulnerable-residents/
A26: Athens
A27: HUNGARY | J27: Forecasted heat wave: info to health care system and general public. During heatwave: provide portable water in public places, water roads and parks, monitor water supply and quality, planned disruption of electricity, special rules for employers and restrictions for public transport. Extraordinary measures: increase hospital beds, ambulance units, hospital staff, cool bodies at morgues, extend opening hours public air-conditioned places and pools, defer non-essential surgery. | K27: yes | L27: yes
A28: Budapest
A29: IRELAND | J29: Yellow : notify those who are at risk because of their location and/or activity, and allow them to take preventative action. Orange : all recipients in the affected areas should prepare themselves in an appropriate way for the anticipated conditions. Red : recipients take action to protect themselves and/or their properties; this could be by moving their families out of the danger zone temporarily; by staying indoors; or by other specific actions
A30: ISRAEL | B30: "so far no directive has been formulated by the Ministry in principle to incorporate considerations of climate change in the decisions made in the Ministry, as proposed in the strategic plan"
A31: Telaviv
A32: ITALY | B32: Piano Operativo Nazionale per la Previsione e la prevenzione degli Effetti delle ondate di calore sulla Salute | C32: Dipartimento di Epidemiologia del Lazio (DEP Lazio), centro di Competenza Nazionale della Protezione Civile, | D32: 2005 | E32: may-september | F32: city level | G32: not in HHAP but part of PAESC or climate adaptation plans | H32: yes mortality/ER visits | I32: annual | J32: Active monitoring of vulnerable groups (specifically identified through administrative and health information registries) by GPs, health care and social services, volunteers (phone calls & home visits by GPs). Activation of emergency protocols in care and retirement homes and in hospitals (postpone non-emergency surgery, discharge planning, staff rotation restrictions, increased hospital beds). Training and Educational campaigns for health and social care staff. | K32: yes | L32: not in HHAP but in Climate adaptation plans or PAESC | M32: yes | N32: yes | O32: www.salute.gov.it/caldo
A33: LATVIA | J33: information campaign for general public and vulnerable groups
A34: NETHERLANDS | J34: Several organizations warn their target groups and regional contacts. | O34: https://bmchealthservres.biomedcentral.com/track/pdf/10.1186/1472-6963-13-135.pdf
A35: NORTH MACEDONIA | C35: Climate change and health committee of the Ministry of Health | D35: 2012 | E35: 1 May - 30 September | I35: Every year | J35: Monitoring, information provided to retirement homes and GPs, installation or maintenance of public drinking fountains & springs, education to public. Phase 1: preventative measures media campaign, home visits to elderly, socially isolated and homeless (red cross); phone line. Phase 2: supply food to elderly and at risk media alert, specific measure for health care preparedness, protection measures for occupationally heat exposed workers; including activating redistribution in residential settings to air-conditioned rooms, extra staff on hotline. Phase 3: Emergency, led by National Crises Management Center | K35: yes | M35: yes | N35: yes
A36: NORWAY
A37: POLAND
A38: Warsaw
A39: PORTUGAL | B39: PLANO DE CONTINGÊNCIA SAÚDE SAZONAL – MÓDULO VERÃO REFERENCIAIS 2021* | C39: Ministério da Saúde. Direção-Geral da Saúde. | D39: 2004 | E39: 1st May till 30th September | J39: Public health emergency telephone used as hotline and reinforced with nursing personnel. Increase capacity of health care services, upscale staff for telephone hotline. Info to public, authorities, health sectors & media. Activate local refuge shelters, monitor need for transportation to places of refuge; notify most vulnerable; increase capacity of health care services. | K39: yes | M39: yes | N39: yes
A40: Beja | J40: Increase capacity of health care services, upscale staff for telephone hotline. | N40: yes
A41: Coimbra | J41: Info to public, authorities, health sectors & media. Activate local refuge shelters, monitor need for transportation to places of refuge; notify most
...

Sheet HPP components
A1: COUNTRY/CITY | B1: CZECH REPUBLIC | C1: ESTONIA | D1: FINLAND | E1: FRANCE | F1: GERMANY | G1: ITALY | H1: NETHERLANDS | I1: NORWAY | J1: POLAND | K1: PORTUGAL | L1: ROMANIA | M1: SERBIA | N1: SPAIN | O1: SWEDEN | P1: SWITZERLAND | Q1: UK
A2: 1. Agreement on a lead body and clear definition of actors’ responsibilities
A3: Clearly defined lead body | B3: 1 | C3: 1 | D3: 1 | E3: 1 | F3: 1 | G3: 1 | H3: 1 | I3: 1 | J3: 1 | K3: 1 | L3: 1 | M3: 1 | N3: 1 | O3: 1 | P3: 1 | Q3: 1
A4: Involvement of > 1 other agencies | E4: 1 | F4: 1 | G4: 1 | H4: 1 | J4: 1 | K4: 1 | L4: 1 | N4: 1 | P4: 1 | Q4: 1
A5: Regular meetings and/or reviews
A6: Inclusion in national disaster preparedness
A7: Cross-border cooperation
A8: Total | B8: =SUM(B3:B7) -> 1 | C8: =SUM(C3:C7) -> 1 | D8: =SUM(D3:D7) -> 1 | E8: =SUM(E3:E7) -> 2 | F8: =SUM(F3:F7) -> 2 | G8: =SUM(G3:G7) -> 2 | H8: =SUM(H3:H7) -> 2 | I8: =SUM(I3:I7) -> 1 | ... Q8: =SUM(Q3:Q7) -> 2
A9: Quality (0=no measures, 1=1 measure, 2=2measures)
A11: 2. Accurate and timely alert systems
A12: Threshold based on climatological/meteorological studies | B12: 1 | J12: 1 | L12: 1
A13: Thresholds based on epidemiological studies | C13: 1 | D13: 1 | E13: 1 | F13: 1 | G13: 1 | H13: 1 | K13: 1 | M13: 1 | N13: 1 | O13: 1 | P13: 1 | Q13: 1
A14: Thresholds based on >= 2 heat indexes | C14: 1 | D14: 1 | E14: 1 | F14: 1 | G14: 1 | I14: 1 | J14: 1 | K14: 1 | L14: 1 | M14: 1 | N14: 1 | P14: 1 | Q14: 1
A15: Thresholds based on duration of the heat wave | C15: 1 | E15: 1 | H15: 1 | I15: 1 | J15: 1 | K15: 1 | M15: 1 | N15: 1 | O15: 1 | P15: 1 | Q15: 1
A16: Regionally adapted definitions | B16: 1 | E16: 1 | F16: 1 | G16: 1 | K16: 1 | M16: 1 | N16: 1 | Q16: 1
A17: Warning is issued well in advance
A18: Different alert levels | B18: 1 | C18: 1 | D18: 1 | E18: 1 | F18: 1 | H18: 1 | J18: 1 | K18: 1 | L18: 1 | M18: 1 | N18: 1 | O18: 1 | P18: 1 | Q18: 1
A19: Alert is communicated following a clear plan | K19: 1 | N19: 1
A20: Total | B20: =SUM(B13:B19) -> 2 | C20: =SUM(C13:C19) -> 4 | D20: =SUM(D13:D19) -> 3 | E20: =SUM(E13:E19) -> 5 | F20: =SUM(F13:F19) -> 4 | G20: =SUM(G13:G19) -> 3 | H20: =SUM(H13:H19) -> 3 | I20: =SUM(I13:I19) -> 2 | ... Q20: =SUM(Q13:Q19) -> 5
A21: Quality (0=no measures, 1=1-3 measure, 2= 4-5 measures)
A23: 3. Health information plan
A24: Clearly defined actors/ recipients/contents | B24: 1 | E24: 1 | F24: 1 | G24: 1 | H24: 1 | K24: 1 | L24: 1 | M24: 1 | N24: 1 | P24: 1 | Q24: 1
A25: Effective dissemination of information (> 1 channel) | B25: 1 | D25: 1 | E25: 1 | F25: 1 | G25: 1 | H25: 1 | I25: 1 | J25: 1 | K25: 1 | L25: 1 | M25: 1 | N25: 1 | P25: 1 | Q25: 1
A26: Quality of advice | K26: 1 | Q26: 1
A27: Public & professionals addressed | B27: 1 | E27: 1 | F27: 1 | G27: 1 | K27: 1 | L27: 1 | M27: 1 | N27: 1 | P27: 1 | Q27: 1
A28: Appropriate timing of information campaign
A29: Total | B29: =SUM(B24:B28) -> 3 | C29: =SUM(C24:C28) -> 0 | D29: =SUM(D24:D28) -> 1 | E29: =SUM(E24:E28) -> 3 | F29: =SUM(F24:F28) -> 3 | G29: =SUM(G24:G28) -> 3 | H29: =SUM(H24:H28) -> 2 | I29: =SUM(I24:I28) -> 1 | ... Q29: =SUM(Q24:Q28) -> 4
A30: Quality (0=no measures, 1=1-2 measure, 2= >2measures)
A32: 4. Reduction in indoor heat exposure
A33: Giving advice | F33: 1 | K33: 1 | Q33: 1
A34: Providing cool rooms/ spaces/fresh water | E34: 1 | Q34: 1
A35: Provision or use of mobile coolers
A36: Planning or support for increased albedo or shading
A37: Planning or support for better insulation
A38: Total | B38: =SUM(B33:B37) -> 0 | C38: =SUM(C33:C37) -> 0 | D38: =SUM(D33:D37) -> 0 | E38: =SUM(E33:E37) -> 1 | F38: =SUM(F33:F37) -> 1 | G38: =SUM(G33:G37) -> 0 | H38: =SUM(H33:H37) -> 0 | I38: =SUM(I33:I37) -> 0 | ... Q38: =SUM(Q33:Q37) -> 2
A39: Quality (0=no measures, 1=measures)
A41: 5. Particular care for vulnerable groups
A42: Identification of relevant groups (> 1) | E42: 1 | F42: 1 | G42: 1 | H42: 1 | I42: 1 | K42: 1 | N42: 1 | Q42: 1
A43: Activation of a telephone service | E43: 1 | F43: 1 | K43: 1 | L43: 1 | N43: 1
A44: Specific measures | E44: 1 | G44: 1 | K44: 1 | N44: 1 | Q44: 1
...

Sheet Component weights
B1: WEIGHT | C1: WEIGHT (survey)
A2: MEASURE
A3: 1. Agreement on a lead body and clear definition of actors’ responsibilities
A4: Clearly defined lead body | B4: 1 | C4: =2 -> 2 | D4: what is important is clear definition of the actor's responsabilities | P4: 0 = 0 | Q4: 1 = 4 | R4: 2 = 18
A5: Involvement of > 1 other agencies | B5: 1 | C5: 1 | D5: depend on the countries, sometimes 1 agency is enough INTERDISCIPLINARIRY | P5: 0 = 2 | Q5: 1 = 10 | R5: 2 = 10
A6: Regular meetings and/or reviews | C6: 1 | P6: 0 = 1 | Q6: 1 = 16 | R6: 2 = 5
A7: Inclusion in nationaldisaster preparedness | C7: 2 | P7: 0 = 0 | Q7: 1 = 9 | R7: 2 = 13
A8: Cross-bordercooperation | C8: 1 | P8: 0 = 7 | Q8: 1 = 12 | R8: 2 = 3
A11: Total | B11: =SUM(B3:B5) -> 2 | C11: =SUM(C4:C8) -> 7 | D11: collaboration of met office and health system
A13: 2. Accurate and timely alert systems
A14: Threshold based on climatological/meteorological studies | B14: 0 | C14: 2 | P14: 0 = 3 | Q14: 1 = 8 | R14: 2 = 11
A15: Thresholds based on epidemiological studies | B15: 1 | C15: 2 | P15: 0 = 0 | Q15: 1 = 5 | R15: 2 = 17
A16: Thresholds based on >= 2 heat indexes | B16: 1 | C16: 1 | E16: not necessary, allows to refine the messages. Not to estmate mortality. Modify to not only average temperature | P16: 0 = 5 | Q16: 1 = 12 | R16: 2 = 5
A17: Thresholds based on duration of the heat wave | B17: 1 | C17: 2 | P17: 0 = 2 | Q17: 1 = 8 | R17: 2 = 12
A18: Regionally adapted definitions | B18: 1 | C18: 2 | P18: 0 = 1 | Q18: 1 = 8 | R18: 2 = 13
A19: Warning is issued well in advance | B19: 1 | C19: 2 | E19: accurate=/= timely appropriate | P19: 0 = 0 | Q19: 1 = 8 | R19: 2 = 13
A20: Different alert levels | B20: 1 | C20: 2 | P20: 0 = 2 | Q20: 1 = 5 | R20: 2 = 15
A21: Alert is communicated following a clear plan | B21: 1 | C21: 2 | P21: 0 = 0 | Q21: 1 = 6 | R21: 2 = 16
A22: Total | B22: =SUM(B14:B21) -> 7 | C22: =SUM(C14:C21) -> 15
A24: 3. Health information plan
A25: Clearly defined actors/ recipients/contents | B25: 1 | C25: 2 | P25: 0 = 0 | Q25: 1 = 6 | R25: 2 = 16
A26: Effective dissemination of information (> 1 channel) | B26: 2 | C26: 2 | E26: important, information targeted for different population | P26: 0 = 1 | Q26: 1 = 2 | R26: 2 = 19
A27: Quality of advice | B27: 2 | C27: 2 | P27: 0 = 0 | Q27: 1 = 6 | R27: 2 = 16
A28: Public & professionals addressed | B28: 1 | C28: 2 | P28: 0 = 0 | Q28: 1 = 7 | R28: 2 = 14
A29: Appropriate timing of information campaign | B29: 1 | C29: 2 | P29: 0 = 1 | Q29: 1 = 9 | R29: 2 = 11
A30: Total | B30: =SUM(B25:B29) -> 7 | C30: =SUM(C25:C29) -> 10
A32: 4. Reduction in indoor heat exposure | H32: chris boyer
A33: Giving advice | B33: 1 | C33: 2 | H33: cboyer10@uw.edu | P33: 0 = 1 | Q33: 1 = 10 | R33: 2 = 11
A34: Providing cool rooms/ spaces/fresh water | B34: 2 | C34: 1 | H34: Jshumake-guillemot@wmo.int | P34: 0 = 0 | Q34: 1 = 12 | R34: 2 = 10
A35: Provision or use of mobile coolers | B35: 1 | C35: 1 | P35: 0 = 1 | Q35: 1 = 13 | R35: 2 = 6
A36: Planning or support forincreased albedo orshading | C36: 1 | P36: 0 = 1 | Q36: 1 = 13 | R36: 2 = 7
A38: Planning or support forbetter insulation | C38: 1 | P38: 0 = 2 | Q38: 1 = 12 | R38: 2 = 7
A39: Total | B39: =SUM(B33:B35) -> 4 | C39: =SUM(C33:C35) -> 4
A41: 5. Particular care for vulnerable groups
A42: Identification of relevant groups (> 1) | B42: 2 | C42: 2 | P42: 0 = 0 | Q42: 1 = 1 | R42: 2 = 18
A43: Activation of a telephone service | B43: 1 | C43: 1 | P43: 0 = 3 | Q43: 1 = 11 | R43: 2 = 8
A44: Specific measures | B44: 2 | C44: 1 | P44: 0 = 1 | Q44: 1 = 12 | R44: 2 = 7
A45: Regular re-assessment of vulnerable population groups | B45: 1 | C45: 1 | P45: 0 = 1 | Q45: 1 = 13 | R45: 2 =7
A46: Information and training for caregivers | B46: 2 | C46: 2 | D46: important, increase the score | P46: 0 = 1 | Q46: 1 = 5 | R46: 2 = 15
A47: Total | B47: =SUM(B42:B46) -> 8 | C47: =SUM(C42:C46) -> 7
...

Sheet HPP components with weights
A1: COUNTRY/CITY | B1: CZECH REPUBLIC | C1: ESTONIA | D1: FINLAND | E1: FRANCE | F1: GERMANY | G1: ITALY | H1: LATVIA | I1: LITHUANIA | J1: NETHERLANDS | K1: NORWAY | L1: POLAND | M1: PORTUGAL | N1: ROMANIA | O1: SERBIA | P1: SPAIN | Q1: SWEDEN | R1: SWITZERLAND | S1: UK | U1: Weight
A2: 1. Agreement on a lead body and clear definition of actors’ responsibilities
A3: Clearly defined lead body | B3: 2 | C3: 2 | D3: 2 | E3: 2 | F3: 2 | G3: 2 | J3: 2 | K3: 2 | L3: 2 | M3: 2 | N3: 2 | O3: 2 | P3: 2 | Q3: 2 | R3: 2 | S3: 2 | U3: 2
A4: Involvement of > 1 other agencies | E4: 1 | F4: 1 | G4: 1 | J4: 1 | L4: 1 | M4: 1 | N4: 1 | P4: 1 | R4: 1 | S4: 1 | U4: 1
A5: Total | B5: =SUM(B3:B4) -> 2 | C5: =SUM(C3:C4) -> 2 | D5: =SUM(D3:D4) -> 2 | E5: =SUM(E3:E4) -> 3 | F5: =SUM(F3:F4) -> 3 | G5: =SUM(G3:G4) -> 3 | H5: =SUM(H3:H4) -> 0 | I5: =SUM(I3:I4) -> 0 | ... S5: =SUM(S3:S4) -> 3 | U5: =SUM(U3:U4) -> 3
A8: 2. Accurate and timely alert systems
A9: Thresholds based on epidemiological studies | C9: 2 | D9: 2 | E9: 2 | F9: 2 | G9: 2 | J9: 2 | M9: 2 | O9: 2 | P9: 2 | Q9: 2 | R9: 2 | S9: 2 | U9: 2
A10: Thresholds based on >= 2 heat indexes | C10: 1 | D10: 1 | E10: 1 | F10: 1 | G10: 1 | K10: 1 | L10: 1 | M10: 1 | N10: 1 | O10: 1 | P10: 1 | R10: 1 | S10: 1 | U10: 1
A11: Thresholds based on duration of the heat wave | C11: 2 | E11: 2 | J11: 2 | K11: 2 | L11: 2 | M11: 2 | O11: 2 | P11: 2 | Q11: 2 | R11: 2 | S11: 2 | U11: 2
A12: Regionally adapted definitions | B12: 2 | E12: 2 | F12: 2 | G12: 2 | M12: 2 | O12: 2 | P12: 2 | S12: 2 | U12: 2
A13: Warning is issued well in advance | U13: 2
A14: Different alert levels | B14: 2 | C14: 2 | D14: 2 | E14: 2 | F14: 2 | J14: 2 | L14: 2 | M14: 2 | N14: 2 | O14: 2 | P14: 2 | Q14: 2 | R14: 2 | S14: 2 | U14: 2
A15: Alert is communicated following a clear plan | M15: 2 | P15: 2 | U15: 2
A16: Total | B16: =SUM(B9:B15) -> 4 | C16: =SUM(C9:C15) -> 7 | D16: =SUM(D9:D15) -> 5 | E16: =SUM(E9:E15) -> 9 | F16: =SUM(F9:F15) -> 7 | G16: =SUM(G9:G15) -> 5 | H16: =SUM(H9:H15) -> 0 | I16: =SUM(I9:I15) -> 0 | ... S16: =SUM(S9:S15) -> 9 | U16: =SUM(U9:U15) -> 13
A19: 3. Health information plan
A20: Clearly defined actors/ recipients/contents | B20: 2 | E20: 2 | F20: 2 | G20: 2 | J20: 2 | M20: 2 | N20: 2 | O20: 2 | P20: 2 | R20: 2 | S20: 2 | U20: 2
A21: Effective dissemination of information (> 1 channel) | B21: 2 | D21: 2 | E21: 2 | F21: 2 | G21: 2 | J21: 2 | K21: 2 | L21: 2 | M21: 2 | N21: 2 | O21: 2 | P21: 2 | R21: 2 | S21: 2 | U21: 2
A22: Quality of advice | M22: 2 | S22: 2 | U22: 2
A23: Public & professionals addressed | B23: 2 | E23: 2 | F23: 2 | G23: 2 | M23: 2 | N23: 2 | O23: 2 | P23: 2 | R23: 2 | S23: 2 | U23: 2
A24: Appropriate timing of information campaign | U24: 2
A25: Total | B25: =SUM(B20:B24) -> 6 | C25: =SUM(C20:C24) -> 0 | D25: =SUM(D20:D24) -> 2 | E25: =SUM(E20:E24) -> 6 | F25: =SUM(F20:F24) -> 6 | G25: =SUM(G20:G24) -> 6 | H25: =SUM(H20:H24) -> 0 | I25: =SUM(I20:I24) -> 0 | ... S25: =SUM(S20:S24) -> 8 | U25: =SUM(U20:U24) -> 10
A28: 4. Reduction in indoor heat exposure
A29: Giving advice | F29: 2 | M29: 2 | S29: 2 | U29: 2
A30: Providing cool rooms/ spaces/fresh water | E30: 1 | S30: 1 | U30: 1
A31: Total | B31: =SUM(B29:B30) -> 0 | C31: =SUM(C29:C30) -> 0 | D31: =SUM(D29:D30) -> 0 | E31: =SUM(E29:E30) -> 1 | F31: =SUM(F29:F30) -> 2 | G31: =SUM(G29:G30) -> 0 | H31: =SUM(H29:H30) -> 0 | I31: =SUM(I29:I30) -> 0 | ... S31: =SUM(S29:S30) -> 3 | U31: =SUM(U29:U30) -> 3
A34: 5. Particular care for vulnerable groups
A35: Identification of relevant groups (> 1) | E35: 2 | F35: 2 | G35: 2 | J35: 2 | M35: 2 | P35: 2 | S35: 2 | U35: 2
A36: Activation of a telephone service | E36: 1 | F36: 1 | M36: 1 | N36: 1 | P36: 1 | U36: 1
A37: Specific measures | E37: 1 | G37: 1 | M37: 1 | P37: 1 | S37: 1 | U37: 1
A38: Regular re-assessment of vulnerable population groups | E38: 1 | G38: 1 | P38: 1 | S38: 1 | U38: 1
A39: Information and training for caregivers | G39: 2 | U39: 2
A40: Total | B40: =SUM(B35:B39) -> 0 | C40: =SUM(C35:C39) -> 0 | D40: =SUM(D35:D39) -> 0 | E40: =SUM(E35:E39) -> 5 | F40: =SUM(F35:F39) -> 3 | G40: =SUM(G35:G39) -> 6 | H40: =SUM(H35:H39) -> 0 | I40: =SUM(I35:I39) -> 0 | ... S40: =SUM(S35:S39) -> 4 | U40: =SUM(U35:U39) -> 7
A43: 6. Preparedness of the health/ social care system
A44: Different levels of action | E44: 1 | P44: 1 | S44: 1 | U44: 1
A45: Increase of capacity of health services | G45: 2 | M45: 2 | N45: 2 | P45: 2 | U45: 2
A46: Heat reduction in healthcare facilities | E46: 2 | F46: 2 | S46: 2 | U46: 2
A47: Special precautions in nursing homes | E47: 2 | F47: 2 | U47: 2
A48: Special resources for patients/public | U48: 1
A49: Improving health-care networks | E49: 1 | M49: 1 | P49: 1 | R49: 1 | S49: 1 | U49: 1
A50: Total | B50: =SUM(B44:B49) -> 0 | C50: =SUM(C44:C49) -> 0 | D50: =SUM(D44:D49) -> 0 | E50: =SUM(E44:E49) -> 6 | F50: =SUM(F44:F49) -> 4 | G50: =SUM(G44:G49) -> 2 | H50: =SUM(H44:H49) -> 0 | I50: =SUM(I44:I49) -> 0 | ... S50: =SUM(S44:S49) -> 4 | U50: =SUM(U44:U49) -> 9
...

Sheet Final HPP classification
A1: COUNTRY/CITY | B1: CZECH REPUBLIC | C1: ESTONIA | D1: FINLAND | E1: FRANCE | F1: GERMANY | G1: ITALY | H1: NETHERLANDS | I1: NORWAY | J1: POLAND | K1: PORTUGAL | L1: ROMANIA | M1: SERBIA | N1: SPAIN | O1: SWEDEN | P1: SWITZERLAND | Q1: UK | T1: COUNTRY/CITY | U1: 1. Agreement on a lead body and clear definition of actors’ responsibilities (/2) | V1: 2. Accurate and timely alert systems (/7) | W1: 3. Health information plan (/7) | X1: 4. Reduction in indoor heat exposure (/4) | Y1: 5. Particular care for vulnerable groups (/8) | Z1: 6. Preparedness of the health/ social care system (/9) | AA1: TOTAL | AB1: stand. Score | AC1: stand.score.max | AD1: CLASS | AE1: CLASS(B)
A2: 1. Agreement on a lead body and clear definition of actors’ responsibilities (/2) | B2: ='HPP components with weights'!B5 -> 2 | C2: ='HPP components with weights'!C5 -> 2 | D2: ='HPP components with weights'!D5 -> 2 | E2: ='HPP components with weights'!E5 -> 3 | F2: ='HPP components with weights'!F5 -> 3 | G2: ='HPP components with weights'!G5 -> 3 | H2: ='HPP components with weights'!J5 -> 3 | I2: ='HPP components with weights'!K5 -> 2 | J2: ='HPP components with weights'!L5 -> 3 | K2: ='HPP components with weights'!M5 -> 3 | L2: ='HPP components with weights'!N5 -> 3 | M2: ='HPP components with weights'!O5 -> 2 | N2: ='HPP components with weights'!P5 -> 3 | O2: ='HPP components with weights'!Q5 -> 2 | ... Q2: ='HPP components with weights'!S5 -> 3 | T2: SWEDEN | U2: 2 | V2: 6 | W2: 0 | X2: 0 | Y2: 0 | Z2: 0 | AA2: 8 | AB2: =AA2/31 -> 0.25806452 | AC2: =AA2/48 -> 0.16666667 | AD2: 1 | AE2: 1
A3: 2. Accurate and timely alert systems (/7) | B3: ='HPP components with weights'!B16 -> 4 | C3: ='HPP components with weights'!C16 -> 7 | D3: ='HPP components with weights'!D16 -> 5 | E3: ='HPP components with weights'!E16 -> 9 | F3: ='HPP components with weights'!F16 -> 7 | G3: ='HPP components with weights'!G16 -> 5 | H3: ='HPP components with weights'!J16 -> 6 | I3: ='HPP components with weights'!K16 -> 3 | J3: ='HPP components with weights'!L16 -> 5 | K3: ='HPP components with weights'!M16 -> 11 | L3: ='HPP components with weights'!N16 -> 3 | M3: ='HPP components with weights'!O16 -> 9 | N3: ='HPP components with weights'!P16 -> 11 | O3: ='HPP components with weights'!Q16 -> 6 | ... Q3: ='HPP components with weights'!S16 -> 9 | T3: FINLAND | U3: 2 | V3: 5 | W3: 2 | X3: 0 | Y3: 0 | Z3: 0 | AA3: 9 | AB3: =AA3/31 -> 0.29032258 | AC3: =AA3/48 -> 0.1875 | AD3: 1 | AE3: 1
A4: 3. Health information plan (/7) | B4: ='HPP components with weights'!B25 -> 6 | C4: ='HPP components with weights'!C25 -> 0 | D4: ='HPP components with weights'!D25 -> 2 | E4: ='HPP components with weights'!E25 -> 6 | F4: ='HPP components with weights'!F25 -> 6 | G4: ='HPP components with weights'!G25 -> 6 | H4: ='HPP components with weights'!J25 -> 4 | I4: ='HPP components with weights'!K25 -> 2 | J4: ='HPP components with weights'!L25 -> 2 | K4: ='HPP components with weights'!M25 -> 8 | L4: ='HPP components with weights'!N25 -> 6 | M4: ='HPP components with weights'!O25 -> 6 | N4: ='HPP components with weights'!P25 -> 6 | O4: ='HPP components with weights'!Q25 -> 0 | ... Q4: ='HPP components with weights'!S25 -> 8 | T4: POLAND | U4: 3 | V4: 5 | W4: 2 | X4: 0 | Y4: 0 | Z4: 0 | AA4: 10 | AB4: =AA4/31 -> 0.32258065 | AC4: =AA4/48 -> 0.20833333 | AD4: 1 | AE4: 1
A5: 4. Reduction in indoor heat exposure (/4) | B5: ='HPP components with weights'!B31 -> 0 | C5: ='HPP components with weights'!C31 -> 0 | D5: ='HPP components with weights'!D31 -> 0 | E5: ='HPP components with weights'!E31 -> 1 | F5: ='HPP components with weights'!F31 -> 2 | G5: ='HPP components with weights'!G31 -> 0 | H5: ='HPP components with weights'!J31 -> 0 | I5: ='HPP components with weights'!K31 -> 0 | J5: ='HPP components with weights'!L31 -> 0 | K5: ='HPP components with weights'!M31 -> 2 | L5: ='HPP components with weights'!N31 -> 0 | M5: ='HPP components with weights'!O31 -> 0 | N5: ='HPP components with weights'!P31 -> 0 | O5: ='HPP components with weights'!Q31 -> 0 | ... Q5: ='HPP components with weights'!S31 -> 3 | T5: CZECHIA | U5: 2 | V5: 4 | W5: 6 | X5: 0 | Y5: 0 | Z5: 0 | AA5: 12 | AB5: =AA5/31 -> 0.38709677 | AC5: =AA5/48 -> 0.25 | AD5: 2 | AE5: 1
A6: 5. Particular care for vulnerable groups (/8) | B6: ='HPP components with weights'!B40 -> 0 | C6: ='HPP components with weights'!C40 -> 0 | D6: ='HPP components with weights'!D40 -> 0 | E6: ='HPP components with weights'!E40 -> 5 | F6: ='HPP components with weights'!F40 -> 3 | G6: ='HPP components with weights'!G40 -> 6 | H6: ='HPP components with weights'!J40 -> 2 | I6: ='HPP components with weights'!K40 -> 0 | J6: ='HPP components with weights'!L40 -> 0 | K6: ='HPP components with weights'!M40 -> 4 | L6: ='HPP components with weights'!N40 -> 1 | M6: ='HPP components with weights'!O40 -> 0 | N6: ='HPP components with weights'!P40 -> 5 | O6: ='HPP components with weights'!Q40 -> 0 | ... Q6: ='HPP components with weights'!S40 -> 4 | T6: NETHERLANDS | U6: 3 | V6: 6 | W6: 4 | X6: 0 | Y6: 2 | Z6: 0 | AA6: 15 | AB6: =AA6/31 -> 0.48387097 | AC6: =AA6/48 -> 0.3125 | AD6: 2 | AE6: 2
A7: 6. Preparedness of the health/ social care system (/9) | B7: ='HPP components with weights'!B50 -> 0 | C7: ='HPP components with weights'!C50 -> 0 | D7: ='HPP components with weights'!D50 -> 0 | E7: ='HPP components with weights'!E50 -> 6 | F7: ='HPP components with weights'!F50 -> 4 | G7: ='HPP components with weights'!G50 -> 2 | H7: ='HPP components with weights'!J50 -> 0 | I7: ='HPP components with weights'!K50 -> 0 | J7: ='HPP components with weights'!L50 -> 0 | K7: ='HPP components with weights'!M50 -> 3 | L7: ='HPP components with weights'!N50 -> 2 | M7: ='HPP components with weights'!O50 -> 0 | N7: ='HPP components with weights'!P50 -> 4 | O7: ='HPP components with weights'!Q50 -> 0 | ... Q7: ='HPP components with weights'!S50 -> 4 | T7: ROMANIA | U7: 3 | V7: 3 | W7: 6 | X7: 0 | Y7: 1 | Z7: 2 | AA7: 15 | AB7: =AA7/31 -> 0.48387097 | AC7: =AA7/48 -> 0.3125 | AD7: 2 | AE7: 2
T8: SERBIA | U8: 2 | V8: 9 | W8: 6 | X8: 0 | Y8: 0 | Z8: 0 | AA8: 17 | AB8: =AA8/31 -> 0.5483871 | AC8: =AA8/48 -> 0.35416667 | AD8: 2 | AE8: 2
T9: SWITZERLAND | U9: 3 | V9: 7 | W9: 6 | X9: 0 | Y9: 0 | Z9: 1 | AA9: 17 | AB9: =AA9/31 -> 0.5483871 | AC9: =AA9/48 -> 0.35416667 | AD9: 2 | AE9: 2
A10: TOTAL | B10: =SUM(B2:B7) -> 12 | C10: =SUM(C2:C7) -> 9 | D10: =SUM(D2:D7) -> 9 | E10: =SUM(E2:E7) -> 30 | F10: =SUM(F2:F7) -> 25 | G10: =SUM(G2:G7) -> 22 | H10: =SUM(H2:H7) -> 15 | I10: =SUM(I2:I7) -> 7 | ... Q10: =SUM(Q2:Q7) -> 31 | T10: ITALY | U10: 3 | V10: 5 | W10: 6 | X10: 0 | Y10: 6 | Z10: 2 | AA10: 22 | AB10: =AA10/31 -> 0.70967742 | AC10: =AA10/48 -> 0.45833333 | AD10: 3 | AE10: 2
T11: GERMANY | U11: 3 | V11: 7 | W11: 6 | X11: 2 | Y11: 3 | Z11: 4 | AA11: 25 | AB11: =AA11/31 -> 0.80645161 | AC11: =AA11/48 -> 0.52083333 | AD11: 3 | AE11: 2
B12: =IF(B10>20,3,IF(B10>10,2,1)) -> 2 | C12: =IF(C10>20,3,IF(C10>10,2,1)) -> 1 | D12: =IF(D10>20,3,IF(D10>10,2,1)) -> 1 | E12: =IF(E10>20,3,IF(E10>10,2,1)) -> 3 | F12: =IF(F10>20,3,IF(F10>10,2,1)) -> 3 | G12: =IF(G10>20,3,IF(G10>10,2,1)) -> 3 | H12: =IF(H10>20,3,IF(H10>10,2,1)) -> 2 | I12: =IF(I10>20,3,IF(I10>10,2,1)) -> 1 | ... Q12: =IF(Q10>20,3,IF(Q10>10,2,1)) -> 3 | T12: SPAIN | U12: 3 | V12: 11 | W12: 6 | X12: 0 | Y12: 5 | Z12: 4 | AA12: 29 | AB12: =AA12/31 -> 0.93548387 | AC12: =AA12/48 -> 0.60416667 | AD12: 3 | AE12: 3
T13: FRANCE | U13: 3 | V13: 9 | W13: 6 | X13: 1 | Y13: 5 | Z13: 6 | AA13: 30 | AB13: =AA13/31 -> 0.96774194 | AC13: =AA13/48 -> 0.625 | AD13: 3 | AE13: 3
T14: PORTUGAL | U14: 3 | V14: 11 | W14: 8 | X14: 2 | Y14: 4 | Z14: 3 | AA14: 31 | AB14: =AA14/31 -> 1 | AC14: =AA14/48 -> 0.64583333 | AD14: 3 | AE14: 3
T15: UK | U15: 3 | V15: 9 | W15: 8 | X15: 3 | Y15: 4 | Z15: 4 | AA15: 31 | AB15: =AA15/31 -> 1 | AC15: =AA15/48 -> 0.64583333 | AD15: 3 | AE15: 3

Sheet HPP score
